{
 "cells": [
  {
   "cell_type": "code",
   "execution_count": 1,
   "metadata": {},
   "outputs": [],
   "source": [
    "from pymongo import MongoClient\n",
    "\n",
    "client = MongoClient('mongodb://localhost:27021,localhost:27019/')\n",
    "\n",
    "\n",
    "\n",
    "\n",
    "\n",
    "client = MongoClient('mongodb://localhost:30001/')"
   ]
  },
  {
   "cell_type": "code",
   "execution_count": 4,
   "metadata": {},
   "outputs": [],
   "source": [
    "\n",
    "config = { \n",
    "    \"_id\" : \"replica-1\",\n",
    "    \"members\" : [\n",
    "        {\n",
    "            \"_id\" : 0,\n",
    "            \"host\" : \"mongo1:27017\"\n",
    "        },\n",
    "        {\n",
    "            \"_id\" : 1,\n",
    "            \"host\" : \"mongo2:27017\"\n",
    "        },\n",
    "        {\n",
    "          \"_id\" : 2,\n",
    "          \"host\" : \"mongo3:27017\"\n",
    "        }\n",
    "        ]\n",
    "}\n"
   ]
  },
  {
   "cell_type": "code",
   "execution_count": 7,
   "metadata": {},
   "outputs": [
    {
     "ename": "TypeError",
     "evalue": "'Collection' object is not callable. If you meant to call the 'initiate' method on a 'Collection' object it is failing because no such method exists.",
     "output_type": "error",
     "traceback": [
      "\u001b[0;31m---------------------------------------------------------------------------\u001b[0m",
      "\u001b[0;31mTypeError\u001b[0m                                 Traceback (most recent call last)",
      "Cell \u001b[0;32mIn[7], line 2\u001b[0m\n\u001b[1;32m      1\u001b[0m db \u001b[38;5;241m=\u001b[39m client[\u001b[38;5;124m'\u001b[39m\u001b[38;5;124mtest\u001b[39m\u001b[38;5;124m'\u001b[39m]\n\u001b[0;32m----> 2\u001b[0m \u001b[43mdb\u001b[49m\u001b[38;5;241;43m.\u001b[39;49m\u001b[43mrs\u001b[49m\u001b[38;5;241;43m.\u001b[39;49m\u001b[43minitiate\u001b[49m\u001b[43m(\u001b[49m\u001b[43mconfig\u001b[49m\u001b[43m)\u001b[49m\n",
      "File \u001b[0;32m/opt/homebrew/lib/python3.11/site-packages/pymongo/collection.py:3213\u001b[0m, in \u001b[0;36mCollection.__call__\u001b[0;34m(self, *args, **kwargs)\u001b[0m\n\u001b[1;32m   3206\u001b[0m \u001b[38;5;28;01mif\u001b[39;00m \u001b[38;5;124m\"\u001b[39m\u001b[38;5;124m.\u001b[39m\u001b[38;5;124m\"\u001b[39m \u001b[38;5;129;01mnot\u001b[39;00m \u001b[38;5;129;01min\u001b[39;00m \u001b[38;5;28mself\u001b[39m\u001b[38;5;241m.\u001b[39m__name:\n\u001b[1;32m   3207\u001b[0m     \u001b[38;5;28;01mraise\u001b[39;00m \u001b[38;5;167;01mTypeError\u001b[39;00m(\n\u001b[1;32m   3208\u001b[0m         \u001b[38;5;124m\"\u001b[39m\u001b[38;5;124m'\u001b[39m\u001b[38;5;124mCollection\u001b[39m\u001b[38;5;124m'\u001b[39m\u001b[38;5;124m object is not callable. If you \u001b[39m\u001b[38;5;124m\"\u001b[39m\n\u001b[1;32m   3209\u001b[0m         \u001b[38;5;124m\"\u001b[39m\u001b[38;5;124mmeant to call the \u001b[39m\u001b[38;5;124m'\u001b[39m\u001b[38;5;132;01m%s\u001b[39;00m\u001b[38;5;124m'\u001b[39m\u001b[38;5;124m method on a \u001b[39m\u001b[38;5;124m'\u001b[39m\u001b[38;5;124mDatabase\u001b[39m\u001b[38;5;124m'\u001b[39m\u001b[38;5;124m \u001b[39m\u001b[38;5;124m\"\u001b[39m\n\u001b[1;32m   3210\u001b[0m         \u001b[38;5;124m\"\u001b[39m\u001b[38;5;124mobject it is failing because no such method \u001b[39m\u001b[38;5;124m\"\u001b[39m\n\u001b[1;32m   3211\u001b[0m         \u001b[38;5;124m\"\u001b[39m\u001b[38;5;124mexists.\u001b[39m\u001b[38;5;124m\"\u001b[39m \u001b[38;5;241m%\u001b[39m \u001b[38;5;28mself\u001b[39m\u001b[38;5;241m.\u001b[39m__name\n\u001b[1;32m   3212\u001b[0m     )\n\u001b[0;32m-> 3213\u001b[0m \u001b[38;5;28;01mraise\u001b[39;00m \u001b[38;5;167;01mTypeError\u001b[39;00m(\n\u001b[1;32m   3214\u001b[0m     \u001b[38;5;124m\"\u001b[39m\u001b[38;5;124m'\u001b[39m\u001b[38;5;124mCollection\u001b[39m\u001b[38;5;124m'\u001b[39m\u001b[38;5;124m object is not callable. If you meant to \u001b[39m\u001b[38;5;124m\"\u001b[39m\n\u001b[1;32m   3215\u001b[0m     \u001b[38;5;124m\"\u001b[39m\u001b[38;5;124mcall the \u001b[39m\u001b[38;5;124m'\u001b[39m\u001b[38;5;132;01m%s\u001b[39;00m\u001b[38;5;124m'\u001b[39m\u001b[38;5;124m method on a \u001b[39m\u001b[38;5;124m'\u001b[39m\u001b[38;5;124mCollection\u001b[39m\u001b[38;5;124m'\u001b[39m\u001b[38;5;124m object it is \u001b[39m\u001b[38;5;124m\"\u001b[39m\n\u001b[1;32m   3216\u001b[0m     \u001b[38;5;124m\"\u001b[39m\u001b[38;5;124mfailing because no such method exists.\u001b[39m\u001b[38;5;124m\"\u001b[39m \u001b[38;5;241m%\u001b[39m \u001b[38;5;28mself\u001b[39m\u001b[38;5;241m.\u001b[39m__name\u001b[38;5;241m.\u001b[39msplit(\u001b[38;5;124m\"\u001b[39m\u001b[38;5;124m.\u001b[39m\u001b[38;5;124m\"\u001b[39m)[\u001b[38;5;241m-\u001b[39m\u001b[38;5;241m1\u001b[39m]\n\u001b[1;32m   3217\u001b[0m )\n",
      "\u001b[0;31mTypeError\u001b[0m: 'Collection' object is not callable. If you meant to call the 'initiate' method on a 'Collection' object it is failing because no such method exists."
     ]
    }
   ],
   "source": [
    "db = client['test']\n",
    "db.rs.initiate(config)"
   ]
  }
 ],
 "metadata": {
  "interpreter": {
   "hash": "767d51c1340bd893661ea55ea3124f6de3c7a262a8b4abca0554b478b1e2ff90"
  },
  "kernelspec": {
   "display_name": "Python 3.9.9 64-bit",
   "language": "python",
   "name": "python3"
  },
  "language_info": {
   "codemirror_mode": {
    "name": "ipython",
    "version": 3
   },
   "file_extension": ".py",
   "mimetype": "text/x-python",
   "name": "python",
   "nbconvert_exporter": "python",
   "pygments_lexer": "ipython3",
   "version": "3.11.6"
  },
  "orig_nbformat": 4
 },
 "nbformat": 4,
 "nbformat_minor": 2
}
